Workbook

Sheet README
A1: EXCEL LLM - A Complete Transformer Language Model in Excel
A3: OVERVIEW
A4: This workbook implements a complete autoregressive transformer language model.
A5: Every computation is done via Excel formulas - no macros or VBA required.
A7: ARCHITECTURE
A8: • Vocabulary: 30 characters (a-z, space, period, comma, newline)
A9: • Embedding Dimension: 8
A10: • Attention Heads: 2 (head dimension: 4)
A11: • FFN Hidden Dimension: 16
A12: • Context Length: 8 tokens
A13: • Activation: GELU
A14: • Normalization: Layer Norm (pre-norm style)
... A51: • Green background: Intermediate calculations

Sheet Config
A1: CONFIGURATION
A2: Parameter | B2: Value | C2: Description
A3: Vocab_Size | B3: 30 | C3: Number of unique tokens
A4: Embed_Dim | B4: 8 | C4: Embedding dimension
A5: Num_Heads | B5: 2 | C5: Number of attention heads
A6: Head_Dim | B6: 4 | C6: Dimension per attention head
A7: FFN_Hidden | B7: 16 | C7: Feed-forward hidden dimension
A8: Context_Len | B8: 8 | C8: Maximum sequence length
A9: Learning_Rate | B9: 0.01 | C9: Gradient descent step size
A10: Epsilon | B10: 1e-05 | C10: LayerNorm epsilon for stability
A11: Example_ID | B11: 1 | C11: Current training example (1-indexed)
A14: Named Ranges:
A15: Use Config!B3 for Vocab_Size, Config!B11 for Example_ID, etc.

Sheet Vocab
A1: VOCABULARY
A2: ID | B2: Character | C2: Display
A3: 0 | B3: a | C3: a
A4: 1 | B4: b | C4: b
A5: 2 | B5: c | C5: c
A6: 3 | B6: d | C6: d
A7: 4 | B7: e | C7: e
A8: 5 | B8: f | C8: f
A9: 6 | B9: g | C9: g
A10: 7 | B10: h | C10: h
A11: 8 | B11: i | C11: i
A12: 9 | B12: j | C12: j
A13: 10 | B13: k | C13: k
A14: 11 | B14: l | C14: l
... A28: 25 | B28: z | C28: z
A29: 26 | C29: space
A30: 27 | B30: . | C30: .
A31: 28 | B31: , | C31: ,
A32: 29 | B32: \n | C32: newline

Sheet Corpus
A1: TRAINING CORPUS
A3: Raw Text:
A4: the cat sat on the mat. the dog ran in the park. the bird flew over the tree. a cat saw a dog. a dog saw a bird. the cat ran to the tree. the dog sat on the mat. the bird sat in the tree.
A6: Current Example: | D6: =INDEX(D9:D100,Config!$B$11) -> 19 | E6: =INDEX(E9:E100,Config!$B$11) -> 7 | F6: =INDEX(F9:F100,Config!$B$11) -> 4 | G6: =INDEX(G9:G100,Config!$B$11) -> 26 | H6: =INDEX(H9:H100,Config!$B$11) -> 2 | I6: =INDEX(I9:I100,Config!$B$11) -> 0 | J6: =INDEX(J9:J100,Config!$B$11) -> 19 | K6: =INDEX(K9:K100,Config!$B$11) -> 26 | L6: =INDEX(L9:L100,Config!$B$11) -> 18
A7: TRAINING EXAMPLES
A8: Example | B8: Input Text | C8: Target | D8: Tok_0 | E8: Tok_1 | F8: Tok_2 | G8: Tok_3 | H8: Tok_4 | I8: Tok_5 | J8: Tok_6 | K8: Tok_7 | L8: Target_ID
A9: 1 | B9: the cat | C9: s | D9: 19 | E9: 7 | F9: 4 | G9: 26 | H9: 2 | I9: 0 | J9: 19 | K9: 26 | L9: 18
A10: 2 | B10: e cat sa | C10: t | D10: 4 | E10: 26 | F10: 2 | G10: 0 | H10: 19 | I10: 26 | J10: 18 | K10: 0 | L10: 19
A11: 3 | B11: cat sat | C11: o | D11: 2 | E11: 0 | F11: 19 | G11: 26 | H11: 18 | I11: 0 | J11: 19 | K11: 26 | L11: 14
A12: 4 | B12: t sat on | D12: 19 | E12: 26 | F12: 18 | G12: 0 | H12: 19 | I12: 26 | J12: 14 | K12: 13 | L12: 26
A13: 5 | B13: sat on t | C13: h | D13: 18 | E13: 0 | F13: 19 | G13: 26 | H13: 14 | I13: 13 | J13: 26 | K13: 19 | L13: 7
A14: 6 | B14: t on the | D14: 19 | E14: 26 | F14: 14 | G14: 13 | H14: 26 | I14: 19 | J14: 7 | K14: 4 | L14: 26
A15: 7 | B15: on the m | C15: a | D15: 14 | E15: 13 | F15: 26 | G15: 19 | H15: 7 | I15: 4 | J15: 26 | K15: 12 | L15: 0
A16: 8 | B16: the mat | C16: . | D16: 26 | E16: 19 | F16: 7 | G16: 4 | H16: 26 | I16: 12 | J16: 0 | K16: 19 | L16: 27
A17: 9 | B17: he mat.\n | C17: t | D17: 7 | E17: 4 | F17: 26 | G17: 12 | H17: 0 | I17: 19 | J17: 27 | K17: 29 | L17: 19
A18: 10 | B18: mat.\nth | C18: e | D18: 26 | E18: 12 | F18: 0 | G18: 19 | H18: 27 | I18: 29 | J18: 19 | K18: 7 | L18: 4
A19: 11 | B19: at.\nthe | C19: d | D19: 0 | E19: 19 | F19: 27 | G19: 29 | H19: 19 | I19: 7 | J19: 4 | K19: 26 | L19: 3
A20: 12 | B20: .\nthe do | C20: g | D20: 27 | E20: 29 | F20: 19 | G20: 7 | H20: 4 | I20: 26 | J20: 3 | K20: 14 | L20: 6
A21: 13 | B21: the dog | C21: r | D21: 19 | E21: 7 | F21: 4 | G21: 26 | H21: 3 | I21: 14 | J21: 6 | K21: 26 | L21: 17
A22: 14 | B22: e dog ra | C22: n | D22: 4 | E22: 26 | F22: 3 | G22: 14 | H22: 6 | I22: 26 | J22: 17 | K22: 0 | L22: 13
A23: 15 | B23: dog ran | C23: i | D23: 3 | E23: 14 | F23: 6 | G23: 26 | H23: 17 | I23: 0 | J23: 13 | K23: 26 | L23: 8
A24: 16 | B24: g ran in | D24: 6 | E24: 26 | F24: 17 | G24: 0 | H24: 13 | I24: 26 | J24: 8 | K24: 13 | L24: 26
A25: 17 | B25: ran in t | C25: h | D25: 17 | E25: 0 | F25: 13 | G25: 26 | H25: 8 | I25: 13 | J25: 26 | K25: 19 | L25: 7
A26: 18 | B26: n in the | D26: 13 | E26: 26 | F26: 8 | G26: 13 | H26: 26 | I26: 19 | J26: 7 | K26: 4 | L26: 26
A27: 19 | B27: in the p | C27: a | D27: 8 | E27: 13 | F27: 26 | G27: 19 | H27: 7 | I27: 4 | J27: 26 | K27: 15 | L27: 0
A28: 20 | B28: the par | C28: k | D28: 26 | E28: 19 | F28: 7 | G28: 4 | H28: 26 | I28: 15 | J28: 0 | K28: 17 | L28: 10
A29: 21 | B29: he park. | C29: \n | D29: 7 | E29: 4 | F29: 26 | G29: 15 | H29: 0 | I29: 17 | J29: 10 | K29: 27 | L29: 29
A30: 22 | B30: park.\nt | C30: h | D30: 26 | E30: 15 | F30: 0 | G30: 17 | H30: 10 | I30: 27 | J30: 29 | K30: 19 | L30: 7
A31: 23 | B31: ark.\nthe | D31: 0 | E31: 17 | F31: 10 | G31: 27 | H31: 29 | I31: 19 | J31: 7 | K31: 4 | L31: 26
A32: 24 | B32: k.\nthe b | C32: i | D32: 10 | E32: 27 | F32: 29 | G32: 19 | H32: 7 | I32: 4 | J32: 26 | K32: 1 | L32: 8
A33: 25 | B33: \nthe bir | C33: d | D33: 29 | E33: 19 | F33: 7 | G33: 4 | H33: 26 | I33: 1 | J33: 8 | K33: 17 | L33: 3
A34: 26 | B34: he bird | C34: f | D34: 7 | E34: 4 | F34: 26 | G34: 1 | H34: 8 | I34: 17 | J34: 3 | K34: 26 | L34: 5
A35: 27 | B35: bird fl | C35: e | D35: 26 | E35: 1 | F35: 8 | G35: 17 | H35: 3 | I35: 26 | J35: 5 | K35: 11 | L35: 4
A36: 28 | B36: ird flew | D36: 8 | E36: 17 | F36: 3 | G36: 26 | H36: 5 | I36: 11 | J36: 4 | K36: 22 | L36: 26
A37: 29 | B37: d flew o | C37: v | D37: 3 | E37: 26 | F37: 5 | G37: 11 | H37: 4 | I37: 22 | J37: 26 | K37: 14 | L37: 21
A38: 30 | B38: flew ove | C38: r | D38: 5 | E38: 11 | F38: 4 | G38: 22 | H38: 26 | I38: 14 | J38: 21 | K38: 4 | L38: 17
A39: 31 | B39: ew over | C39: t | D39: 4 | E39: 22 | F39: 26 | G39: 14 | H39: 21 | I39: 4 | J39: 17 | K39: 26 | L39: 19
A40: 32 | B40: over th | C40: e | D40: 26 | E40: 14 | F40: 21 | G40: 4 | H40: 17 | I40: 26 | J40: 19 | K40: 7 | L40: 4
A41: 33 | B41: ver the | C41: t | D41: 21 | E41: 4 | F41: 17 | G41: 26 | H41: 19 | I41: 7 | J41: 4 | K41: 26 | L41: 19
A42: 34 | B42: r the tr | C42: e | D42: 17 | E42: 26 | F42: 19 | G42: 7 | H42: 4 | I42: 26 | J42: 19 | K42: 17 | L42: 4
...

Sheet Embeddings
A1: TOKEN EMBEDDINGS (Vocab_Size × Embed_Dim) | R1: Key References:
A2: Token_ID | B2: E0 | C2: E1 | D2: E2 | E2: E3 | F2: E4 | G2: E5 | H2: E6 | I2: E7 | R2: LN1_Output_Start_Row: | S2: 90
A3: 0 | B3: 0.0497 | C3: -0.0138 | D3: 0.0648 | E3: 0.1523 | F3: -0.0234 | G3: -0.0234 | H3: 0.1579 | I3: 0.0767 | R3: Combined_Emb_Start_Row: | S3: 63
A4: 1 | B4: -0.0469 | C4: 0.0543 | D4: -0.0463 | E4: -0.0466 | F4: 0.0242 | G4: -0.1913 | H4: -0.1725 | I4: -0.0562
A5: 2 | B5: -0.1013 | C5: 0.0314 | D5: -0.0908 | E5: -0.1412 | F5: 0.1466 | G5: -0.0226 | H5: 0.0068 | I5: -0.1425
A6: 3 | B6: -0.0544 | C6: 0.0111 | D6: -0.1151 | E6: 0.0376 | F6: -0.0601 | G6: -0.0292 | H6: -0.0602 | I6: 0.1852
A7: 4 | B7: -0.0013 | C7: -0.1058 | D7: 0.0823 | E7: -0.1221 | F7: 0.0209 | G7: -0.196 | H7: -0.1328 | I7: 0.0197
A8: 5 | B8: 0.0738 | C8: 0.0171 | D8: -0.0116 | E8: -0.0301 | F8: -0.1479 | G8: -0.072 | H8: -0.0461 | I8: 0.1057
A9: 6 | B9: 0.0344 | C9: -0.1763 | D9: 0.0324 | E9: -0.0385 | F9: -0.0677 | G9: 0.0612 | H9: 0.1031 | I9: 0.0931
A10: 7 | B10: -0.0839 | C10: -0.0309 | D10: 0.0331 | E10: 0.0976 | F10: -0.0479 | G10: -0.0186 | H10: -0.1106 | I10: -0.1196
A11: 8 | B11: 0.0813 | C11: 0.1356 | D11: -0.0072 | E11: 0.1004 | F11: 0.0362 | G11: -0.0645 | H11: 0.0361 | I11: 0.1538
A12: 9 | B12: -0.0036 | C12: 0.1565 | D12: -0.262 | E12: 0.0822 | F12: 0.0087 | G12: -0.0299 | H12: 0.0092 | I12: -0.1988
A13: 10 | B13: -0.022 | C13: 0.0357 | D13: 0.1478 | E13: -0.0518 | F13: -0.0808 | G13: -0.0502 | H13: 0.0915 | I13: 0.0329
A14: 11 | B14: -0.053 | C14: 0.0513 | D14: 0.0097 | E14: 0.0969 | F14: -0.0702 | G14: -0.0328 | H14: -0.0392 | I14: -0.1464
A15: 12 | B15: 0.0296 | C15: 0.0261 | D15: 0.0005 | E15: -0.0235 | F15: -0.1415 | G15: -0.0421 | H15: -0.0343 | I15: -0.0802
... A32: 29 | B32: 0.0046 | C32: -0.0652 | D32: 0.2144 | E32: 0.0634 | F32: -0.2025 | G32: 0.0186 | H32: -0.0662 | I32: 0.0852
A35: POSITIONAL EMBEDDINGS (Context_Len × Embed_Dim)
A36: Position | B36: P0 | C36: P1 | D36: P2 | E36: P3 | F36: P4 | G36: P5 | H36: P6 | I36: P7
A37: 0 | B37: -0.0793 | C37: -0.0115 | D37: 0.0505 | E37: 0.0866 | F37: -0.12 | G37: -0.0335 | H37: -0.0475 | I37: -0.0653
A38: 1 | B38: 0.1765 | C38: 0.0405 | D38: -0.1261 | E38: 0.0918 | F38: 0.2122 | G38: 0.1032 | H38: -0.1519 | I38: -0.0484
A39: 2 | B39: 0.1267 | C39: -0.0708 | D39: 0.0444 | E39: 0.0775 | F39: -0.0927 | G39: -0.006 | H39: -0.3241 | I39: -0.1024
A40: 3 | B40: -0.0253 | C40: -0.1248 | D40: 0.1632 | E40: -0.143 | F40: -0.044 | G40: 0.0131 | H40: 0.1441 | I40: -0.1436
A41: 4 | B41: 0.1163 | C41: 0.001 | D41: -0.0982 | E41: 0.0462 | F41: 0.0199 | G41: -0.06 | H41: 0.007 | I41: -0.0385
A42: 5 | B42: 0.0114 | C42: 0.0662 | D42: 0.1586 | E42: -0.1238 | F42: 0.2133 | G42: -0.1952 | H42: -0.0152 | I42: 0.0588
A43: 6 | B43: 0.0281 | C43: -0.0623 | D43: -0.0208 | E43: -0.0493 | F43: -0.0589 | G43: 0.085 | H43: 0.0357 | I43: -0.0693
A44: 7 | B44: 0.09 | C44: 0.0307 | D44: 0.0813 | E44: 0.063 | F44: -0.0829 | G44: -0.056 | H44: 0.0747 | I44: 0.061
A47: INPUT SEQUENCE EMBEDDINGS
A48: Step 1: Look up token embeddings from input sequence
A49: Position | B49: TE0 | C49: TE1 | D49: TE2 | E49: TE3 | F49: TE4 | G49: TE5 | H49: TE6 | I49: TE7
A50: 0 | B50: =INDEX($B$3:$B$32,Corpus!D$6+1) -> -0.068 | C50: =INDEX($C$3:$C$32,Corpus!D$6+1) -> 0.0232 | D50: =INDEX($D$3:$D$32,Corpus!D$6+1) -> 0.0293 | E50: =INDEX($E$3:$E$32,Corpus!D$6+1) -> -0.0714 | F50: =INDEX($F$3:$F$32,Corpus!D$6+1) -> 0.1866 | G50: =INDEX($G$3:$G$32,Corpus!D$6+1) -> 0.0474 | H50: =INDEX($H$3:$H$32,Corpus!D$6+1) -> -0.1191 | I50: =INDEX($I$3:$I$32,Corpus!D$6+1) -> 0.0657
A51: 1 | B51: =INDEX($B$3:$B$32,Corpus!E$6+1) -> -0.0839 | C51: =INDEX($C$3:$C$32,Corpus!E$6+1) -> -0.0309 | D51: =INDEX($D$3:$D$32,Corpus!E$6+1) -> 0.0331 | E51: =INDEX($E$3:$E$32,Corpus!E$6+1) -> 0.0976 | F51: =INDEX($F$3:$F$32,Corpus!E$6+1) -> -0.0479 | G51: =INDEX($G$3:$G$32,Corpus!E$6+1) -> -0.0186 | H51: =INDEX($H$3:$H$32,Corpus!E$6+1) -> -0.1106 | I51: =INDEX($I$3:$I$32,Corpus!E$6+1) -> -0.1196
A52: 2 | B52: =INDEX($B$3:$B$32,Corpus!F$6+1) -> -0.0013 | C52: =INDEX($C$3:$C$32,Corpus!F$6+1) -> -0.1058 | D52: =INDEX($D$3:$D$32,Corpus!F$6+1) -> 0.0823 | E52: =INDEX($E$3:$E$32,Corpus!F$6+1) -> -0.1221 | F52: =INDEX($F$3:$F$32,Corpus!F$6+1) -> 0.0209 | G52: =INDEX($G$3:$G$32,Corpus!F$6+1) -> -0.196 | H52: =INDEX($H$3:$H$32,Corpus!F$6+1) -> -0.1328 | I52: =INDEX($I$3:$I$32,Corpus!F$6+1) -> 0.0197
A53: 3 | B53: =INDEX($B$3:$B$32,Corpus!G$6+1) -> 0.0515 | C53: =INDEX($C$3:$C$32,Corpus!G$6+1) -> 0.3853 | D53: =INDEX($D$3:$D$32,Corpus!G$6+1) -> 0.0571 | E53: =INDEX($E$3:$E$32,Corpus!G$6+1) -> 0.1136 | F53: =INDEX($F$3:$F$32,Corpus!G$6+1) -> 0.0954 | G53: =INDEX($G$3:$G$32,Corpus!G$6+1) -> 0.0651 | H53: =INDEX($H$3:$H$32,Corpus!G$6+1) -> -0.0315 | I53: =INDEX($I$3:$I$32,Corpus!G$6+1) -> 0.0759
A54: 4 | B54: =INDEX($B$3:$B$32,Corpus!H$6+1) -> -0.1013 | C54: =INDEX($C$3:$C$32,Corpus!H$6+1) -> 0.0314 | D54: =INDEX($D$3:$D$32,Corpus!H$6+1) -> -0.0908 | E54: =INDEX($E$3:$E$32,Corpus!H$6+1) -> -0.1412 | F54: =INDEX($F$3:$F$32,Corpus!H$6+1) -> 0.1466 | G54: =INDEX($G$3:$G$32,Corpus!H$6+1) -> -0.0226 | H54: =INDEX($H$3:$H$32,Corpus!H$6+1) -> 0.0068 | I54: =INDEX($I$3:$I$32,Corpus!H$6+1) -> -0.1425
A55: 5 | B55: =INDEX($B$3:$B$32,Corpus!I$6+1) -> 0.0497 | C55: =INDEX($C$3:$C$32,Corpus!I$6+1) -> -0.0138 | D55: =INDEX($D$3:$D$32,Corpus!I$6+1) -> 0.0648 | E55: =INDEX($E$3:$E$32,Corpus!I$6+1) -> 0.1523 | F55: =INDEX($F$3:$F$32,Corpus!I$6+1) -> -0.0234 | G55: =INDEX($G$3:$G$32,Corpus!I$6+1) -> -0.0234 | H55: =INDEX($H$3:$H$32,Corpus!I$6+1) -> 0.1579 | I55: =INDEX($I$3:$I$32,Corpus!I$6+1) -> 0.0767
A56: 6 | B56: =INDEX($B$3:$B$32,Corpus!J$6+1) -> -0.068 | C56: =INDEX($C$3:$C$32,Corpus!J$6+1) -> 0.0232 | D56: =INDEX($D$3:$D$32,Corpus!J$6+1) -> 0.0293 | E56: =INDEX($E$3:$E$32,Corpus!J$6+1) -> -0.0714 | F56: =INDEX($F$3:$F$32,Corpus!J$6+1) -> 0.1866 | G56: =INDEX($G$3:$G$32,Corpus!J$6+1) -> 0.0474 | H56: =INDEX($H$3:$H$32,Corpus!J$6+1) -> -0.1191 | I56: =INDEX($I$3:$I$32,Corpus!J$6+1) -> 0.0657
A57: 7 | B57: =INDEX($B$3:$B$32,Corpus!K$6+1) -> 0.0515 | C57: =INDEX($C$3:$C$32,Corpus!K$6+1) -> 0.3853 | D57: =INDEX($D$3:$D$32,Corpus!K$6+1) -> 0.0571 | E57: =INDEX($E$3:$E$32,Corpus!K$6+1) -> 0.1136 | F57: =INDEX($F$3:$F$32,Corpus!K$6+1) -> 0.0954 | G57: =INDEX($G$3:$G$32,Corpus!K$6+1) -> 0.0651 | H57: =INDEX($H$3:$H$32,Corpus!K$6+1) -> -0.0315 | I57: =INDEX($I$3:$I$32,Corpus!K$6+1) -> 0.0759
A60: COMBINED EMBEDDINGS (Token + Position)
A61: Step 2: Add positional embeddings
A62: Position | B62: X0 | C62: X1 | D62: X2 | E62: X3 | F62: X4 | G62: X5 | H62: X6 | I62: X7
...

Sheet Attention
A1: MULTI-HEAD SELF-ATTENTION | R1: Residual_Row: | S1: 218
A3: W_Q (Query Weights)
B4: 0.0257 | C4: -0.0908 | D4: -0.0379 | E4: -0.0535 | F4: 0.0858 | G4: -0.0413 | H4: 0.0498 | I4: 0.201
B5: 0.1263 | C5: -0.0439 | D5: -0.0346 | E5: 0.0455 | F5: -0.1669 | G5: -0.0862 | H5: 0.0493 | I5: -0.0124
B6: 0.1935 | C6: -0.0618 | D6: -0.1047 | E6: -0.089 | F6: 0.0014 | G6: -0.0161 | H6: 0.223 | I6: -0.0399
B7: 0.0054 | C7: 0.0884 | D7: -0.0108 | E7: 0.0556 | F7: 0.0395 | G7: 0.0837 | H7: -0.1408 | I7: 0.0808
B8: -0.0138 | C8: 0.0187 | D8: -0.0387 | E8: 0.1659 | F8: -0.2047 | G8: 0.1399 | H8: -0.0679 | I8: 0.1529
B9: 0.1221 | C9: 0.1015 | D9: 0.0828 | E9: 0.2266 | F9: -0.0595 | G9: -0.0581 | H9: -0.0656 | I9: 0.0925
B10: -0.1299 | C10: 0.1011 | D10: -0.0288 | E10: -0.1068 | F10: -0.1078 | G10: -0.0797 | H10: -0.1486 | I10: 0.0514
B11: 0.0852 | C11: 0.0959 | D11: -0.0626 | E11: 0.0308 | F11: 0.0005 | G11: 0.0692 | H11: 0.0445 | I11: 0.009
A13: W_K (Key Weights)
B14: -0.1858 | C14: -0.0167 | D14: 0.0111 | E14: -0.0695 | F14: -0.0269 | G14: -0.1299 | H14: -0.0321 | I14: 0.0506
B15: 0.2089 | C15: -0.1013 | D15: -0.0024 | E15: -0.0961 | F15: -0.0093 | G15: -0.0224 | H15: 0.0833 | I15: 0.0974
B16: 0.0163 | C16: -0.0114 | D16: 0.1186 | E16: 0.018 | F16: 0.1516 | G16: -0.1634 | H16: 0.1782 | I16: -0.0618
B17: -0.1086 | C17: -0.0045 | D17: -0.1164 | E17: 0.0569 | F17: -0.0463 | G17: 0.0287 | H17: -0.0977 | I17: -0.0222
B18: 0.0097 | C18: -0.0188 | D18: 0.1592 | E18: 0.0586 | F18: 0.0204 | G18: -0.1857 | H18: 0.0378 | I18: 0.1236
B19: -0.069 | C19: -0.0198 | D19: -0.3026 | E19: -0.1246 | F19: -0.2084 | G19: 0.0104 | H19: -0.015 | I19: -0.0106
B20: -0.0437 | C20: 0.1019 | D20: -0.1233 | E20: -0.0074 | F20: 0.0596 | G20: -0.0179 | H20: -0.0091 | I20: -0.0825
B21: -0.0335 | C21: 0.0718 | D21: -0.2019 | E21: -0.0158 | F21: -0.0584 | G21: -0.007 | H21: 0.1773 | I21: -0.0447
A23: W_V (Value Weights)
B24: 0.1489 | C24: 0.11 | D24: 0.003 | E24: 0.0087 | F24: 0.0181 | G24: -0.0825 | H24: 0.0627 | I24: -0.0613
B25: 0.0036 | C25: -0.2196 | D25: -0.0863 | E25: 0.0535 | F25: -0.1123 | G25: 0.0334 | H25: -0.0507 | I25: 0.099
B26: 0.1258 | C26: 0.0178 | D26: -0.0015 | E26: 0.004 | F26: -0.0021 | G26: 0.1192 | H26: 0.2505 | I26: -0.1333
B27: -0.1028 | C27: 0.1363 | D27: -0.1142 | E27: -0.1372 | F27: 0.2115 | G27: -0.0274 | H27: -0.025 | I27: -0.0509
B28: 0.0581 | C28: -0.1133 | D28: 0.1774 | E28: 0.0753 | F28: -0.0052 | G28: -0.0552 | H28: 0.0108 | I28: 0.1044
B29: 0.2617 | C29: 0.1509 | D29: 0.1013 | E29: 0.0043 | F29: 0.1233 | G29: -0.0346 | H29: 0.0332 | I29: 0.1171
B30: 0.0607 | C30: -0.0665 | D30: -0.1533 | E30: 0.0501 | F30: 0.0135 | G30: 0.093 | H30: 0.0058 | I30: -0.038
B31: 0.1054 | C31: 0.0996 | D31: -0.2109 | E31: -0.1519 | F31: 0.013 | G31: -0.0065 | H31: -0.0187 | I31: 0.0824
A33: W_O (Output Projection)
B34: 0.2015 | C34: -0.1031 | D34: -0.0068 | E34: -0.0025 | F34: 0.0205 | G34: -0.1224 | H34: 0.0467 | I34: 0.0037
B35: 0.2039 | C35: 0.0385 | D35: -0.0701 | E35: -0.1497 | F35: -0.0098 | G35: -0.075 | H35: -0.0424 | I35: 0.0346
B36: 0.0235 | C36: 0.0194 | D36: 0.1392 | E36: 0.0408 | F36: 0.2713 | G36: 0.0161 | H36: -0.0407 | I36: -0.1497
B37: -0.1314 | C37: 0.0907 | D37: 0.0649 | E37: -0.009 | F37: -0.0224 | G37: -0.0888 | H37: -0.0166 | I37: 0.0123
B38: -0.2018 | C38: 0.0725 | D38: -0.2027 | E38: 0.0337 | F38: -0.0045 | G38: 0.0292 | H38: -0.0648 | I38: 0.1693
B39: 0.0718 | C39: 0.0635 | D39: -0.0179 | E39: -0.0075 | F39: 0.0886 | G39: 0.1302 | H39: 0.14 | I39: -0.0046
B40: 0.0057 | C40: 0.0331 | D40: -0.0262 | E40: -0.0709 | F40: 0.0166 | G40: 0.0473 | H40: 0.0524 | I40: -0.0076
B41: -0.0658 | C41: 0.0499 | D41: 0.0401 | E41: -0.0919 | F41: 0.0949 | G41: 0.076 | H41: -0.0042 | I41: -0.1254
A44: Q, K, V PROJECTIONS
A46: Q = X @ W_Q
A47: Pos | B47: Q0 | C47: Q1 | D47: Q2 | E47: Q3 | F47: Q4 | G47: Q5 | H47: Q6 | I47: Q7
...

Sheet FFN
A1: LAYER NORM 2 (Pre-FFN) | R1: Resid2_Row: | S1: 111
A3: Gamma (γ): | B3: 1 | C3: 1 | D3: 1 | E3: 1 | F3: 1 | G3: 1 | H3: 1 | I3: 1
A4: Beta (β): | B4: 0 | C4: 0 | D4: 0 | E4: 0 | F4: 0 | G4: 0 | H4: 0 | I4: 0
A6: Position | B6: Mean | C6: Var
A7: 0 | B7: =AVERAGE(Attention!B218:I218) -> 0.0017921515 | C7: =VARP(Attention!B218:I218) -> 0.015300627
A8: 1 | B8: =AVERAGE(Attention!B219:I219) -> 0.0060750623 | C8: =VARP(Attention!B219:I219) -> 0.037028324
A9: 2 | B9: =AVERAGE(Attention!B220:I220) -> -0.091716651 | C9: =VARP(Attention!B220:I220) -> 0.038364612
A10: 3 | B10: =AVERAGE(Attention!B221:I221) -> 0.0946972 | C10: =VARP(Attention!B221:I221) -> 0.01705449
A11: 4 | B11: =AVERAGE(Attention!B222:I222) -> -0.0299819 | C11: =VARP(Attention!B222:I222) -> 0.019308548
A12: 5 | B12: =AVERAGE(Attention!B223:I223) -> 0.090893528 | C12: =VARP(Attention!B223:I223) -> 0.021664097
A13: 6 | B13: =AVERAGE(Attention!B224:I224) -> 0.010565898 | C13: =VARP(Attention!B224:I224) -> 0.013515627
A14: 7 | B14: =AVERAGE(Attention!B225:I225) -> 0.14698709 | C14: =VARP(Attention!B225:I225) -> 0.015252058
A18: LN2 Output
B19: LN2_0 | C19: LN2_1 | D19: LN2_2 | E19: LN2_3 | F19: LN2_4 | G19: LN2_5 | H19: LN2_6 | I19: LN2_7
A20: 0 | B20: =B3*(Attention!B$218-B7)/SQRT(C7+Config!$B$10)+B4 -> -1.4168488 | C20: =C3*(Attention!C$218-B7)/SQRT(C7+Config!$B$10)+C4 -> 0.24922364 | D20: =D3*(Attention!D$218-B7)/SQRT(C7+Config!$B$10)+D4 -> 1.0217677 | E20: =E3*(Attention!E$218-B7)/SQRT(C7+Config!$B$10)+E4 -> 0.11963654 | F20: =F3*(Attention!F$218-B7)/SQRT(C7+Config!$B$10)+F4 -> 1.5070641 | G20: =G3*(Attention!G$218-B7)/SQRT(C7+Config!$B$10)+G4 -> 0.53733547 | H20: =H3*(Attention!H$218-B7)/SQRT(C7+Config!$B$10)+H4 -> -1.376775 | I20: =I3*(Attention!I$218-B7)/SQRT(C7+Config!$B$10)+I4 -> -0.64140374
A21: 1 | B21: =B3*(Attention!B$219-B8)/SQRT(C8+Config!$B$10)+B4 -> 0.17634171 | C21: =C3*(Attention!C$219-B8)/SQRT(C8+Config!$B$10)+C4 -> 0.15209276 | D21: =D3*(Attention!D$219-B8)/SQRT(C8+Config!$B$10)+D4 -> -0.31958315 | E21: =E3*(Attention!E$219-B8)/SQRT(C8+Config!$B$10)+E4 -> 0.98020112 | F21: =F3*(Attention!F$219-B8)/SQRT(C8+Config!$B$10)+F4 -> 1.4789402 | G21: =G3*(Attention!G$219-B8)/SQRT(C8+Config!$B$10)+G4 -> 0.47943423 | H21: =H3*(Attention!H$219-B8)/SQRT(C8+Config!$B$10)+H4 -> -1.7185602 | I21: =I3*(Attention!I$219-B8)/SQRT(C8+Config!$B$10)+I4 -> -1.2288667
A22: 2 | B22: =B3*(Attention!B$220-B9)/SQRT(C9+Config!$B$10)+B4 -> 1.1330179 | C22: =C3*(Attention!C$220-B9)/SQRT(C9+Config!$B$10)+C4 -> -0.35703162 | D22: =D3*(Attention!D$220-B9)/SQRT(C9+Config!$B$10)+D4 -> 1.2238402 | E22: =E3*(Attention!E$220-B9)/SQRT(C9+Config!$B$10)+E4 -> 0.19116408 | F22: =F3*(Attention!F$220-B9)/SQRT(C9+Config!$B$10)+F4 -> 0.61622914 | G22: =G3*(Attention!G$220-B9)/SQRT(C9+Config!$B$10)+G4 -> -0.55422204 | H22: =H3*(Attention!H$220-B9)/SQRT(C9+Config!$B$10)+H4 -> -2.0823979 | I22: =I3*(Attention!I$220-B9)/SQRT(C9+Config!$B$10)+I4 -> -0.17059984
A23: 3 | B23: =B3*(Attention!B$221-B10)/SQRT(C10+Config!$B$10)+B4 -> -0.66162105 | C23: =C3*(Attention!C$221-B10)/SQRT(C10+Config!$B$10)+C4 -> 1.3660732 | D23: =D3*(Attention!D$221-B10)/SQRT(C10+Config!$B$10)+D4 -> 1.4119511 | E23: =E3*(Attention!E$221-B10)/SQRT(C10+Config!$B$10)+E4 -> -0.8423221 | F23: =F3*(Attention!F$221-B10)/SQRT(C10+Config!$B$10)+F4 -> 0.36692426 | G23: =G3*(Attention!G$221-B10)/SQRT(C10+Config!$B$10)+G4 -> -0.039586533 | H23: =H3*(Attention!H$221-B10)/SQRT(C10+Config!$B$10)+H4 -> 0.085244676 | I23: =I3*(Attention!I$221-B10)/SQRT(C10+Config!$B$10)+I4 -> -1.6866635
A24: 4 | B24: =B3*(Attention!B$222-B11)/SQRT(C11+Config!$B$10)+B4 -> -0.024521596 | C24: =C3*(Attention!C$222-B11)/SQRT(C11+Config!$B$10)+C4 -> 0.5396864 | D24: =D3*(Attention!D$222-B11)/SQRT(C11+Config!$B$10)+D4 -> -0.54385875 | E24: =E3*(Attention!E$222-B11)/SQRT(C11+Config!$B$10)+E4 -> -0.27667673 | F24: =F3*(Attention!F$222-B11)/SQRT(C11+Config!$B$10)+F4 -> 2.1267556 | G24: =G3*(Attention!G$222-B11)/SQRT(C11+Config!$B$10)+G4 -> -0.34218903 | H24: =H3*(Attention!H$222-B11)/SQRT(C11+Config!$B$10)+H4 -> 0.15412206 | I24: =I3*(Attention!I$222-B11)/SQRT(C11+Config!$B$10)+I4 -> -1.6333179
A25: 5 | B25: =B3*(Attention!B$223-B12)/SQRT(C12+Config!$B$10)+B4 -> -0.50502626 | C25: =C3*(Attention!C$223-B12)/SQRT(C12+Config!$B$10)+C4 -> -0.1850835 | D25: =D3*(Attention!D$223-B12)/SQRT(C12+Config!$B$10)+D4 -> 1.4689171 | E25: =E3*(Attention!E$223-B12)/SQRT(C12+Config!$B$10)+E4 -> -0.20640251 | F25: =F3*(Attention!F$223-B12)/SQRT(C12+Config!$B$10)+F4 -> 1.2015753 | G25: =G3*(Attention!G$223-B12)/SQRT(C12+Config!$B$10)+G4 -> -1.9762137 | H25: =H3*(Attention!H$223-B12)/SQRT(C12+Config!$B$10)+H4 -> 0.36286966 | I25: =I3*(Attention!I$223-B12)/SQRT(C12+Config!$B$10)+I4 -> -0.16063608
A26: 6 | B26: =B3*(Attention!B$224-B13)/SQRT(C13+Config!$B$10)+B4 -> -0.77711606 | C26: =C3*(Attention!C$224-B13)/SQRT(C13+Config!$B$10)+C4 -> -0.35440003 | D26: =D3*(Attention!D$224-B13)/SQRT(C13+Config!$B$10)+D4 -> 0.7490947 | E26: =E3*(Attention!E$224-B13)/SQRT(C13+Config!$B$10)+E4 -> -0.90278116 | F26: =F3*(Attention!F$224-B13)/SQRT(C13+Config!$B$10)+F4 -> 1.803042 | G26: =G3*(Attention!G$224-B13)/SQRT(C13+Config!$B$10)+G4 -> 1.1305598 | H26: =H3*(Attention!H$224-B13)/SQRT(C13+Config!$B$10)+H4 -> -0.84269271 | I26: =I3*(Attention!I$224-B13)/SQRT(C13+Config!$B$10)+I4 -> -0.80570652
A27: 7 | B27: =B3*(Attention!B$225-B14)/SQRT(C14+Config!$B$10)+B4 -> -0.37746142 | C27: =C3*(Attention!C$225-B14)/SQRT(C14+Config!$B$10)+C4 -> 2.2214183 | D27: =D3*(Attention!D$225-B14)/SQRT(C14+Config!$B$10)+D4 -> 0.62824436 | E27: =E3*(Attention!E$225-B14)/SQRT(C14+Config!$B$10)+E4 -> 0.4795284 | F27: =F3*(Attention!F$225-B14)/SQRT(C14+Config!$B$10)+F4 -> -0.51415534 | G27: =G3*(Attention!G$225-B14)/SQRT(C14+Config!$B$10)+G4 -> -0.97663716 | H27: =H3*(Attention!H$225-B14)/SQRT(C14+Config!$B$10)+H4 -> -0.79210779 | I27: =I3*(Attention!I$225-B14)/SQRT(C14+Config!$B$10)+I4 -> -0.66882936
A30: FFN WEIGHTS
A32: W1 (Embed → Hidden)
B33: -0.0751 | C33: 0.1316 | D33: 0.1246 | E33: -0.1605 | F33: -0.1468 | G33: -0.1715 | H33: 0.1859 | I33: 0.0088 | J33: -0.0052 | K33: 0.0555 | L33: -0.0963 | M33: -0.018 | N33: -0.1183 | O33: 0.0605 | P33: -0.0952 | Q33: 0.0361
B34: 0.1061 | C34: -0.0117 | D34: 0.0826 | E34: -0.121 | F34: -0.1191 | G34: 0.022 | H34: -0.0213 | I34: -0.1411 | J34: -0.0483 | K34: 0.1202 | L34: -0.0706 | M34: 0.0025 | N34: -0.0391 | O34: 0.0193 | P34: 0.0349 | Q34: 0.0591
B35: 0.052 | C35: 0.0825 | D35: 0.0426 | E35: 0.0196 | F35: -0.0514 | G35: -0.3074 | H35: -0.0395 | I35: -0.0795 | J35: -0.0703 | K35: -0.1737 | L35: 0.0751 | M35: -0.1864 | N35: 0.0419 | O35: -0.0235 | P35: 0.0432 | Q35: 0.087
B36: 0.2009 | C36: 0.1372 | D36: 0.1059 | E36: 0.1445 | F36: 0.0049 | G36: 0.009 | H36: -0.048 | I36: 0.0301 | J36: 0.1113 | K36: -0.0019 | L36: -0.0001 | M36: -0.0639 | N36: 0.1595 | O36: 0.0019 | P36: 0.0561 | Q36: -0.0198
B37: 0.0463 | C37: -0.1819 | D37: 0.0133 | E37: -0.0617 | F37: 0.1308 | G37: 0.0776 | H37: -0.028 | I37: -0.0724 | J37: -0.0943 | K37: 0.0562 | L37: -0.0693 | M37: 0.1702 | N37: -0.1052 | O37: -0.0661 | P37: -0.1011 | Q37: -0.1459
B38: 0.0391 | C38: -0.081 | D38: 0.1158 | E38: 0.0032 | F38: -0.1897 | G38: -0.0865 | H38: -0.0057 | I38: 0.1231 | J38: -0.0534 | K38: -0.0336 | L38: -0.1556 | M38: 0.1219 | N38: -0.2258 | O38: 0.0221 | P38: -0.0055 | Q38: 0.0281
B39: 0.0599 | C39: 0.1027 | D39: 0.0007 | E39: -0.1753 | F39: 0.1549 | G39: -0.0645 | H39: 0.0879 | I39: -0.0318 | J39: 0.0727 | K39: -0.0066 | L39: -0.0451 | M39: 0.0854 | N39: -0.2536 | O39: -0.0387 | P39: -0.0021 | Q39: 0.0316
B40: -0.063 | C40: -0.198 | D40: 0.0277 | E40: -0.1236 | F40: 0.0573 | G40: 0.0318 | H40: -0.0079 | I40: 0.1477 | J40: 0.1128 | K40: -0.1085 | L40: -0.1851 | M40: 0.1333 | N40: 0.2241 | O40: -0.0783 | P40: 0.0244 | Q40: -0.101
A42: b1 (Hidden bias)
B43: 0 | C43: 0 | D43: 0 | E43: 0 | F43: 0 | G43: 0 | H43: 0 | I43: 0 | J43: 0 | K43: 0 | L43: 0 | M43: 0 | N43: 0 | O43: 0 | P43: 0 | Q43: 0
A46: W2 (Hidden → Embed)
B47: -0.0718 | C47: 0.2901 | D47: 0.0386 | E47: 0.004 | F47: 0.0108 | G47: -0.1285 | H47: 0.0342 | I47: 0.1832
B48: 0.1449 | C48: -0.0528 | D48: -0.0911 | E48: 0.0651 | F48: 0.0016 | G48: -0.0137 | H48: -0.0778 | I48: 0.0797
B49: 0.0038 | C49: -0.006 | D49: 0.0007 | E49: 0.0385 | F49: -0.1027 | G49: -0.108 | H49: -0.2574 | I49: 0.0305
B50: 0.1892 | C50: 0.1016 | D50: -0.0044 | E50: -0.1158 | F50: -0.0396 | G50: -0.067 | H50: 0.032 | I50: -0.0296
B51: 0.0407 | C51: -0.0445 | D51: -0.1391 | E51: 0.1676 | F51: -0.1381 | G51: -0.1277 | H51: -0.0776 | I51: -0.0593
...

Sheet Output
A1: FINAL LAYER NORM | AP1: Prob_Row: | AQ1: 37
AP2: Logits_Row: | AQ2: 31
A3: Gamma (γ): | B3: 1 | C3: 1 | D3: 1 | E3: 1 | F3: 1 | G3: 1 | H3: 1 | I3: 1
A4: Beta (β): | B4: 0 | C4: 0 | D4: 0 | E4: 0 | F4: 0 | G4: 0 | H4: 0 | I4: 0
A6: Statistics (last position only)
A7: Mean: | B7: =AVERAGE(FFN!B118:I118) -> 0.16534162
A8: Variance: | B8: =VARP(FFN!B118:I118) -> 0.019085394
A10: LayerNorm Output (last position)
B11: LN_0 | C11: LN_1 | D11: LN_2 | E11: LN_3 | F11: LN_4 | G11: LN_5 | H11: LN_6 | I11: LN_7
B12: =B3*(FFN!B$118-$B$7)/SQRT($B$8+Config!$B$10)+B4 -> -0.089303978 | C12: =C3*(FFN!C$118-$B$7)/SQRT($B$8+Config!$B$10)+C4 -> 2.3353957 | D12: =D3*(FFN!D$118-$B$7)/SQRT($B$8+Config!$B$10)+D4 -> 0.00055985401 | E12: =E3*(FFN!E$118-$B$7)/SQRT($B$8+Config!$B$10)+E4 -> 0.43148932 | F12: =F3*(FFN!F$118-$B$7)/SQRT($B$8+Config!$B$10)+F4 -> -0.65963967 | G12: =G3*(FFN!G$118-$B$7)/SQRT($B$8+Config!$B$10)+G4 -> -1.1783233 | H12: =H3*(FFN!H$118-$B$7)/SQRT($B$8+Config!$B$10)+H4 -> -0.71254327 | I12: =I3*(FFN!I$118-$B$7)/SQRT($B$8+Config!$B$10)+I4 -> -0.12763466
A15: UNEMBEDDING MATRIX (Embed_Dim × Vocab_Size)
A16: (Tied with token embeddings)
B17: 0 | C17: 1 | D17: 2 | E17: 3 | F17: 4 | G17: 5 | H17: 6 | I17: 7 | J17: 8 | K17: 9 | L17: 10 | M17: 11 | N17: 12 | O17: 13 | P17: 14 | Q17: 15 | R17: 16 | S17: 17 | T17: 18 | U17: 19 | V17: 20 | W17: 21 | X17: 22 | Y17: 23 | Z17: 24 | AA17: 25 | AB17: 26 | AC17: 27 | AD17: 28 | AE17: 29
A18: E0 | B18: =Embeddings!B$3 -> 0.0497 | C18: =Embeddings!B$4 -> -0.0469 | D18: =Embeddings!B$5 -> -0.1013 | E18: =Embeddings!B$6 -> -0.0544 | F18: =Embeddings!B$7 -> -0.0013 | G18: =Embeddings!B$8 -> 0.0738 | H18: =Embeddings!B$9 -> 0.0344 | I18: =Embeddings!B$10 -> -0.0839 | J18: =Embeddings!B$11 -> 0.0813 | K18: =Embeddings!B$12 -> -0.0036 | L18: =Embeddings!B$13 -> -0.022 | M18: =Embeddings!B$14 -> -0.053 | N18: =Embeddings!B$15 -> 0.0296 | O18: =Embeddings!B$16 -> -0.0161 | P18: =Embeddings!B$17 -> 0.006 | Q18: =Embeddings!B$18 -> 0.0791 | R18: =Embeddings!B$19 -> 0.01 | S18: =Embeddings!B$20 -> -0.0783 | T18: =Embeddings!B$21 -> 0.026 | U18: =Embeddings!B$22 -> -0.068 | V18: =Embeddings!B$23 -> -0.0975 | W18: =Embeddings!B$24 -> -0.0245 | X18: =Embeddings!B$25 -> 0.0013 | Y18: =Embeddings!B$26 -> -0.0223 | Z18: =Embeddings!B$27 -> 0.0214 | AA18: =Embeddings!B$28 -> 0.0358 | AB18: =Embeddings!B$29 -> 0.0515 | AC18: =Embeddings!B$30 -> -0.0773 | AD18: =Embeddings!B$31 -> -0.0472 | AE18: =Embeddings!B$32 -> 0.0046
A19: E1 | B19: =Embeddings!C$3 -> -0.0138 | C19: =Embeddings!C$4 -> 0.0543 | D19: =Embeddings!C$5 -> 0.0314 | E19: =Embeddings!C$6 -> 0.0111 | F19: =Embeddings!C$7 -> -0.1058 | G19: =Embeddings!C$8 -> 0.0171 | H19: =Embeddings!C$9 -> -0.1763 | I19: =Embeddings!C$10 -> -0.0309 | J19: =Embeddings!C$11 -> 0.1356 | K19: =Embeddings!C$12 -> 0.1565 | L19: =Embeddings!C$13 -> 0.0357 | M19: =Embeddings!C$14 -> 0.0513 | N19: =Embeddings!C$15 -> 0.0261 | O19: =Embeddings!C$16 -> 0.0404 | P19: =Embeddings!C$17 -> 0.2463 | Q19: =Embeddings!C$18 -> -0.0909 | R19: =Embeddings!C$19 -> -0.0503 | S19: =Embeddings!C$20 -> -0.0322 | T19: =Embeddings!C$21 -> 0.0782 | U19: =Embeddings!C$22 -> 0.0232 | V19: =Embeddings!C$23 -> 0.0787 | W19: =Embeddings!C$24 -> -0.0754 | X19: =Embeddings!C$25 -> 0.1454 | Y19: =Embeddings!C$26 -> 0.0714 | Z19: =Embeddings!C$27 -> -0.1246 | AA19: =Embeddings!C$28 -> 0.0561 | AB19: =Embeddings!C$29 -> 0.3853 | AC19: =Embeddings!C$30 -> -0.0237 | AD19: =Embeddings!C$31 -> 0.1089 | AE19: =Embeddings!C$32 -> -0.0652
A20: E2 | B20: =Embeddings!D$3 -> 0.0648 | C20: =Embeddings!D$4 -> -0.0463 | D20: =Embeddings!D$5 -> -0.0908 | E20: =Embeddings!D$6 -> -0.1151 | F20: =Embeddings!D$7 -> 0.0823 | G20: =Embeddings!D$8 -> -0.0116 | H20: =Embeddings!D$9 -> 0.0324 | I20: =Embeddings!D$10 -> 0.0331 | J20: =Embeddings!D$11 -> -0.0072 | K20: =Embeddings!D$12 -> -0.262 | L20: =Embeddings!D$13 -> 0.1478 | M20: =Embeddings!D$14 -> 0.0097 | N20: =Embeddings!D$15 -> 0.0005 | O20: =Embeddings!D$16 -> 0.1886 | P20: =Embeddings!D$17 -> -0.0192 | Q20: =Embeddings!D$18 -> 0.1403 | R20: =Embeddings!D$19 -> -0.1551 | S20: =Embeddings!D$20 -> 0.0814 | T20: =Embeddings!D$21 -> -0.1237 | U20: =Embeddings!D$22 -> 0.0293 | V20: =Embeddings!D$23 -> 0.1159 | W20: =Embeddings!D$24 -> -0.089 | X20: =Embeddings!D$25 -> -0.0265 | Y20: =Embeddings!D$26 -> 0.0473 | Z20: =Embeddings!D$27 -> 0.0173 | AA20: =Embeddings!D$28 -> 0.1083 | AB20: =Embeddings!D$29 -> 0.0571 | AC20: =Embeddings!D$30 -> -0.0485 | AD20: =Embeddings!D$31 -> 0.0064 | AE20: =Embeddings!D$32 -> 0.2144
A21: E3 | B21: =Embeddings!E$3 -> 0.1523 | C21: =Embeddings!E$4 -> -0.0466 | D21: =Embeddings!E$5 -> -0.1412 | E21: =Embeddings!E$6 -> 0.0376 | F21: =Embeddings!E$7 -> -0.1221 | G21: =Embeddings!E$8 -> -0.0301 | H21: =Embeddings!E$9 -> -0.0385 | I21: =Embeddings!E$10 -> 0.0976 | J21: =Embeddings!E$11 -> 0.1004 | K21: =Embeddings!E$12 -> 0.0822 | L21: =Embeddings!E$13 -> -0.0518 | M21: =Embeddings!E$14 -> 0.0969 | N21: =Embeddings!E$15 -> -0.0235 | O21: =Embeddings!E$16 -> 0.0175 | P21: =Embeddings!E$17 -> 0.0302 | Q21: =Embeddings!E$18 -> -0.1402 | R21: =Embeddings!E$19 -> 0.0069 | S21: =Embeddings!E$20 -> -0.1231 | T21: =Embeddings!E$21 -> -0.132 | U21: =Embeddings!E$22 -> -0.0714 | V21: =Embeddings!E$23 -> -0.0821 | W21: =Embeddings!E$24 -> -0.0816 | X21: =Embeddings!E$25 -> 0.272 | Y21: =Embeddings!E$26 -> -0.0073 | Z21: =Embeddings!E$27 -> 0.0385 | AA21: =Embeddings!E$28 -> 0.1054 | AB21: =Embeddings!E$29 -> 0.1136 | AC21: =Embeddings!E$30 -> 0.0082 | AD21: =Embeddings!E$31 -> -0.1078 | AE21: =Embeddings!E$32 -> 0.0634
A22: E4 | B22: =Embeddings!F$3 -> -0.0234 | C22: =Embeddings!F$4 -> 0.0242 | D22: =Embeddings!F$5 -> 0.1466 | E22: =Embeddings!F$6 -> -0.0601 | F22: =Embeddings!F$7 -> 0.0209 | G22: =Embeddings!F$8 -> -0.1479 | H22: =Embeddings!F$9 -> -0.0677 | I22: =Embeddings!F$10 -> -0.0479 | J22: =Embeddings!F$11 -> 0.0362 | K22: =Embeddings!F$12 -> 0.0087 | L22: =Embeddings!F$13 -> -0.0808 | M22: =Embeddings!F$14 -> -0.0702 | N22: =Embeddings!F$15 -> -0.1415 | O22: =Embeddings!F$16 -> 0.0258 | P22: =Embeddings!F$17 -> -0.0035 | Q22: =Embeddings!F$18 -> 0.0587 | R22: =Embeddings!F$19 -> -0.1062 | S22: =Embeddings!F$20 -> 0.0227 | T22: =Embeddings!F$21 -> 0.0522 | U22: =Embeddings!F$22 -> 0.1866 | V22: =Embeddings!F$23 -> 0.0963 | W22: =Embeddings!F$24 -> -0.0077 | X22: =Embeddings!F$25 -> 0.0626 | Y22: =Embeddings!F$26 -> -0.0847 | Z22: =Embeddings!F$27 -> -0.0884 | AA22: =Embeddings!F$28 -> -0.1378 | AB22: =Embeddings!F$29 -> 0.0954 | AC22: =Embeddings!F$30 -> 0.2315 | AD22: =Embeddings!F$31 -> -0.0715 | AE22: =Embeddings!F$32 -> -0.2025
A23: E5 | B23: =Embeddings!G$3 -> -0.0234 | C23: =Embeddings!G$4 -> -0.1913 | D23: =Embeddings!G$5 -> -0.0226 | E23: =Embeddings!G$6 -> -0.0292 | F23: =Embeddings!G$7 -> -0.196 | G23: =Embeddings!G$8 -> -0.072 | H23: =Embeddings!G$9 -> 0.0612 | I23: =Embeddings!G$10 -> -0.0186 | J23: =Embeddings!G$11 -> -0.0645 | K23: =Embeddings!G$12 -> -0.0299 | L23: =Embeddings!G$13 -> -0.0502 | M23: =Embeddings!G$14 -> -0.0328 | N23: =Embeddings!G$15 -> -0.0421 | O23: =Embeddings!G$16 -> -0.0074 | P23: =Embeddings!G$17 -> -0.1169 | Q23: =Embeddings!G$18 -> 0.219 | R23: =Embeddings!G$19 -> 0.0474 | S23: =Embeddings!G$20 -> 0.1307 | T23: =Embeddings!G$21 -> 0.0297 | U23: =Embeddings!G$22 -> 0.0474 | V23: =Embeddings!G$23 -> 0.0413 | W23: =Embeddings!G$24 -> 0.0341 | X23: =Embeddings!G$25 -> -0.0857 | Y23: =Embeddings!G$26 -> -0.1515 | Z23: =Embeddings!G$27 -> 0.0154 | AA23: =Embeddings!G$28 -> -0.0938 | AB23: =Embeddings!G$29 -> 0.0651 | AC23: =Embeddings!G$30 -> -0.1867 | AD23: =Embeddings!G$31 -> 0.068 | AE23: =Embeddings!G$32 -> 0.0186
A24: E6 | B24: =Embeddings!H$3 -> 0.1579 | C24: =Embeddings!H$4 -> -0.1725 | D24: =Embeddings!H$5 -> 0.0068 | E24: =Embeddings!H$6 -> -0.0602 | F24: =Embeddings!H$7 -> -0.1328 | G24: =Embeddings!H$8 -> -0.0461 | H24: =Embeddings!H$9 -> 0.1031 | I24: =Embeddings!H$10 -> -0.1106 | J24: =Embeddings!H$11 -> 0.0361 | K24: =Embeddings!H$12 -> 0.0092 | L24: =Embeddings!H$13 -> 0.0915 | M24: =Embeddings!H$14 -> -0.0392 | N24: =Embeddings!H$15 -> -0.0343 | O24: =Embeddings!H$16 -> -0.1919 | P24: =Embeddings!H$17 -> 0.1143 | Q24: =Embeddings!H$18 -> -0.0991 | R24: =Embeddings!H$19 -> -0.0919 | S24: =Embeddings!H$20 -> -0.1607 | T24: =Embeddings!H$21 -> 0.025 | U24: =Embeddings!H$22 -> -0.1191 | V24: =Embeddings!H$23 -> 0.0822 | W24: =Embeddings!H$24 -> 0.0277 | X24: =Embeddings!H$25 -> -0.1071 | Y24: =Embeddings!H$26 -> -0.0447 | Z24: =Embeddings!H$27 -> 0.0058 | AA24: =Embeddings!H$28 -> 0.0515 | AB24: =Embeddings!H$29 -> -0.0315 | AC24: =Embeddings!H$30 -> 0.0686 | AD24: =Embeddings!H$31 -> -0.073 | AE24: =Embeddings!H$32 -> -0.0662
A25: E7 | B25: =Embeddings!I$3 -> 0.0767 | C25: =Embeddings!I$4 -> -0.0562 | D25: =Embeddings!I$5 -> -0.1425 | E25: =Embeddings!I$6 -> 0.1852 | F25: =Embeddings!I$7 -> 0.0197 | G25: =Embeddings!I$8 -> 0.1057 | H25: =Embeddings!I$9 -> 0.0931 | I25: =Embeddings!I$10 -> -0.1196 | J25: =Embeddings!I$11 -> 0.1538 | K25: =Embeddings!I$12 -> -0.1988 | L25: =Embeddings!I$13 -> 0.0329 | M25: =Embeddings!I$14 -> -0.1464 | N25: =Embeddings!I$15 -> -0.0802 | O25: =Embeddings!I$16 -> -0.0027 | P25: =Embeddings!I$17 -> 0.0752 | Q25: =Embeddings!I$18 -> -0.0566 | R25: =Embeddings!I$19 -> 0.155 | S25: =Embeddings!I$20 -> 0.0185 | T25: =Embeddings!I$21 -> 0.0346 | U25: =Embeddings!I$22 -> 0.0657 | V25: =Embeddings!I$23 -> 0.1897 | W25: =Embeddings!I$24 -> 0.0827 | X25: =Embeddings!I$25 -> 0.0482 | Y25: =Embeddings!I$26 -> 0.0856 | Z25: =Embeddings!I$27 -> -0.1143 | AA25: =Embeddings!I$28 -> 0.0514 | AB25: =Embeddings!I$29 -> 0.0759 | AC25: =Embeddings!I$30 -> -0.1613 | AD25: =Embeddings!I$31 -> 0.0216 | AE25: =Embeddings!I$32 -> 0.0852
A28: LOGITS (LN_out @ Unembed)
B30: a | C30: b | D30: c | E30: d | F30: e | G30: f | H30: g | I30: h | J30: i | K30: j | L30: k | M30: l | N30: m | O30: n | P30: o | Q30: p | R30: q | S30: r | T30: s | U30: t | V30: u | W30: v | X30: w | Y30: x | Z30: y | AA30: z | AB30: _ | AC30: . | AD30: , | AE30: \n
A31: Logit | B31: =B12*B18+C12*B19+D12*B20+E12*B21+F12*B22+G12*B23+H12*B24+I12*B25 -> -0.050206594 | C31: =B12*C18+C12*C19+D12*C20+E12*C21+F12*C22+G12*C23+H12*C24+I12*C25 -> 0.45040377 | D31: =B12*D18+C12*D19+D12*D20+E12*D21+F12*D22+G12*D23+H12*D24+I12*D25 -> -0.035329632 | E31: =B12*E18+C12*E19+D12*E20+E12*E21+F12*E22+G12*E23+H12*E24+I12*E25 -> 0.14024914 | F31: =B12*F18+C12*F19+D12*F20+E12*F21+F12*F22+G12*F23+H12*F24+I12*F25 -> 0.0096687005 | G31: =B12*G18+C12*G19+D12*G20+E12*G21+F12*G22+G12*G23+H12*G24+I12*G25 -> 0.22210756 | H31: =B12*H18+C12*H19+D12*H20+E12*H21+F12*H22+G12*H23+H12*H24+I12*H25 -> -0.5441983 | I31: =B12*I18+C12*I19+D12*I20+E12*I21+F12*I22+G12*I23+H12*I24+I12*I25 -> 0.12504671 | J31: =B12*J18+C12*J19+D12*J20+E12*J21+F12*J22+G12*J23+H12*J24+I12*J25 -> 0.35950662 | K31: =B12*K18+C12*K19+D12*K20+E12*K21+F12*K22+G12*K23+H12*K24+I12*K25 -> 0.44944404 | L31: =B12*L18+C12*L19+D12*L20+E12*L21+F12*L22+G12*L23+H12*L24+I12*L25 -> 0.10612374 | M31: =B12*M18+C12*M19+D12*M20+E12*M21+F12*M22+G12*M23+H12*M24+I12*M25 -> 0.29792878 | N31: =B12*N18+C12*N19+D12*N20+E12*N21+F12*N22+G12*N23+H12*N24+I12*N25 -> 0.22579367 | O31: =B12*O18+C12*O19+D12*O20+E12*O21+F12*O22+G12*O23+H12*O24+I12*O25 -> 0.23222699 | P31: =B12*P18+C12*P19+D12*P20+E12*P21+F12*P22+G12*P23+H12*P24+I12*P25 -> 0.63670528 | Q31: =B12*Q18+C12*Q19+D12*Q20+E12*Q21+F12*Q22+G12*Q23+H12*Q24+I12*Q25 -> -0.49870416 | R31: =B12*R18+C12*R19+D12*R20+E12*R21+F12*R22+G12*R23+H12*R24+I12*R25 -> -0.055572439 | S31: =B12*S18+C12*S19+D12*S20+E12*S21+F12*S22+G12*S23+H12*S24+I12*S25 -> -0.17811422 | T31: =B12*T18+C12*T19+D12*T20+E12*T21+F12*T22+G12*T23+H12*T24+I12*T25 -> 0.031621064 | U31: =B12*U18+C12*U19+D12*U20+E12*U21+F12*U22+G12*U23+H12*U24+I12*U25 -> -0.073001064 | V31: =B12*V18+C12*V19+D12*V20+E12*V21+F12*V22+G12*V23+H12*V24+I12*V25 -> -0.03782901 | W31: =B12*W18+C12*W19+D12*W20+E12*W21+F12*W22+G12*W23+H12*W24+I12*W25 -> -0.27455468 | X31: =B12*X18+C12*X19+D12*X20+E12*X21+F12*X22+G12*X23+H12*X24+I12*X25 -> 0.58665096 | Y31: =B12*Y18+C12*Y19+D12*Y20+E12*Y21+F12*Y22+G12*Y23+H12*Y24+I12*Y25 -> 0.42092796 | Z31: =B12*Z18+C12*Z19+D12*Z20+E12*Z21+F12*Z22+G12*Z23+H12*Z24+I12*Z25 -> -0.22565753 | AA31: =B12*AA18+C12*AA19+D12*AA20+E12*AA21+F12*AA22+G12*AA23+H12*AA24+I12*AA25 -> 0.3315269 | AB31: =B12*AB18+C12*AB19+D12*AB20+E12*AB21+F12*AB22+G12*AB23+H12*AB24+I12*AB25 -> 0.81739714 | AC31: =B12*AC18+C12*AC19+D12*AC20+E12*AC21+F12*AC22+G12*AC23+H12*AC24+I12*AC25 -> -0.0059412424 | AD31: =B12*AD18+C12*AD19+D12*AD20+E12*AD21+F12*AD22+G12*AD23+H12*AD24+I12*AD25 -> 0.22832578 | AE31: =B12*AE18+C12*AE19+D12*AE20+E12*AE21+F12*AE22+G12*AE23+H12*AE24+I12*AE25 -> 0.022753968
A34: PROBABILITIES (Softmax)
B36: a | C36: b | D36: c | E36: d | F36: e | G36: f | H36: g | I36: h | J36: i | K36: j | L36: k | M36: l | N36: m | O36: n | P36: o | Q36: p | R36: q | S36: r | T36: s | U36: t | V36: u | W36: v | X36: w | Y36: x | Z36: y | AA36: z | AB36: _ | AC36: . | AD36: , | AE36: \n
A37: Prob | B37: =EXP(B31)/SUMPRODUCT(EXP(B31:AE31)) -> 0.026716636 | C37: =EXP(C31)/SUMPRODUCT(EXP(B31:AE31)) -> 0.04407518 | D37: =EXP(D31)/SUMPRODUCT(EXP(B31:AE31)) -> 0.02711707 | E37: =EXP(E31)/SUMPRODUCT(EXP(B31:AE31)) -> 0.032321808 | F37: =EXP(F31)/SUMPRODUCT(EXP(B31:AE31)) -> 0.028365163 | G37: =EXP(G31)/SUMPRODUCT(EXP(B31:AE31)) -> 0.035078928 | H37: =EXP(H31)/SUMPRODUCT(EXP(B31:AE31)) -> 0.016302113 | I37: =EXP(I31)/SUMPRODUCT(EXP(B31:AE31)) -> 0.031834154 | J37: =EXP(J31)/SUMPRODUCT(EXP(B31:AE31)) -> 0.040245559 | K37: =EXP(K31)/SUMPRODUCT(EXP(B31:AE31)) -> 0.0440329 | L37: =EXP(L31)/SUMPRODUCT(EXP(B31:AE31)) -> 0.031237421 | M37: =EXP(M31)/SUMPRODUCT(EXP(B31:AE31)) -> 0.037842084 | N37: =EXP(N31)/SUMPRODUCT(EXP(B31:AE31)) -> 0.035208471 | O37: =EXP(O31)/SUMPRODUCT(EXP(B31:AE31)) -> 0.035435709 | P37: =EXP(P31)/SUMPRODUCT(EXP(B31:AE31)) -> 0.053101136 | Q37: =EXP(Q31)/SUMPRODUCT(EXP(B31:AE31)) -> 0.017060893 | R37: =EXP(R31)/SUMPRODUCT(EXP(B31:AE31)) -> 0.026573663 | S37: =EXP(S31)/SUMPRODUCT(EXP(B31:AE31)) -> 0.023508894 | T37: =EXP(T31)/SUMPRODUCT(EXP(B31:AE31)) -> 0.02899473 | U37: =EXP(U31)/SUMPRODUCT(EXP(B31:AE31)) -> 0.026114533 | V37: =EXP(V31)/SUMPRODUCT(EXP(B31:AE31)) -> 0.027049378 | W37: =EXP(W31)/SUMPRODUCT(EXP(B31:AE31)) -> 0.021347579 | X37: =EXP(X31)/SUMPRODUCT(EXP(B31:AE31)) -> 0.050508619 | Y37: =EXP(Y31)/SUMPRODUCT(EXP(B31:AE31)) -> 0.042794988 | Z37: =EXP(Z31)/SUMPRODUCT(EXP(B31:AE31)) -> 0.022417357 | AA37: =EXP(AA31)/SUMPRODUCT(EXP(B31:AE31)) -> 0.039135107 | AB37: =EXP(AB31)/SUMPRODUCT(EXP(B31:AE31)) -> 0.063617601 | AC37: =EXP(AC31)/SUMPRODUCT(EXP(B31:AE31)) -> 0.027925822 | AD37: =EXP(AD31)/SUMPRODUCT(EXP(B31:AE31)) -> 0.035297736 | AE37: =EXP(AE31)/SUMPRODUCT(EXP(B31:AE31)) -> 0.028738768
A40: PREDICTION
A42: Predicted ID: | B42: =MATCH(MAX(B37:AE37),B37:AE37,0)-1 -> 26
A43: Predicted Char: | B43: =INDEX(Vocab!B$3:B$32,$B$42+1)
A44: Max Probability: | B44: =MAX(B37:AE37) -> 0.063617601
A46: Target ID: | B46: =Corpus!L$6 -> 18
A47: Target Char: | B47: =INDEX(Vocab!B$3:B$32,$B$46+1) -> s

Sheet Loss
A1: CROSS-ENTROPY LOSS
A3: Cross-Entropy Loss = -log(P(target))
A5: Target Token ID: | B5: =Corpus!L$6 -> 18
A7: Probability of Target: | B7: =INDEX(Output!$B$37:$AE$37,1,$B$5+1) -> 0.02899473
A9: Cross-Entropy Loss: | B9: =-LN($B$7) -> 3.5406412
A11: Note: Lower loss = better prediction
A14: ADDITIONAL METRICS
A16: Perplexity: | B16: =EXP($B$9) -> 34.489026
A17: Correct Prediction: | B17: =IF(Output!$B$42=$B$5,"YES","NO") -> NO

Sheet Gradients
A1: GRADIENT COMPUTATION
A3: Method: Numerical Differentiation
A4: ∂L/∂w ≈ (L(w+ε) - L(w-ε)) / (2ε)
A6: Epsilon (ε): | B6: 0.001
A8: Current Loss: | B8: =Loss!$B$9 -> 3.5406412
A10: HOW TO COMPUTE GRADIENTS MANUALLY:
A12: 1. Note the current loss value above
A13: 2. Go to a weight you want to update (e.g., Embeddings token weight)
A14: 3. Add epsilon (0.001) to the weight
A15: 4. Record the new loss (L+)
A16: 5. Subtract 2*epsilon from the weight (original - epsilon)
A17: 6. Record the new loss (L-)
A18: 7. Gradient = (L+ - L-) / (2 * epsilon)
A19: 8. Restore the weight to its original value
A20: 9. Use gradient in Train sheet to update weight
A24: SAMPLE GRADIENT WORKSHEET
A26: Weight Location: | B26: Embeddings!B3
A27: Original Value: | B27: =INDIRECT($B$26) -> 0.0497
A28: L+ (w + ε):
A29: L- (w - ε):
A30: Gradient: | B30: =IF(AND($B$28<>"",$B$29<>""),($B$28-$B$29)/(2*$B$6),"")
A32: Updated Weight: | B32: =IF($B$30<>"", $B$27 - Config!$B$9*$B$30, "")

Sheet Train
A1: TRAINING - WEIGHT UPDATES
A3: Learning Rate: | B3: =Config!$B$9 -> 0.01
A4: Current Example: | B4: =Config!$B$11 -> 1
A5: Current Loss: | B5: =Loss!$B$9 -> 3.5406412
A8: TRAINING PROCEDURE
A10: Step 1: Run forward pass (automatic via formulas)
A11: Step 2: Check Loss sheet for current loss
A12: Step 3: For each weight you want to update:
A13: a. Go to Gradients sheet
A14: b. Enter weight cell reference
A15: c. Compute gradient by perturbing weight
A16: d. Calculate: new_weight = old_weight - lr * gradient
A17: Step 4: Update weight in original location
A18: Step 5: Change Example_ID in Config to next example
A19: Step 6: Repeat for all examples (one epoch)
A21: TIP: Focus on output layer weights first,
... A28: Weight Cell:
A29: Current Value: | B29: =IF($B$28<>"",INDIRECT($B$28),"")
A30: Gradient:
A31: New Value: | B31: =IF(AND($B$28<>"",$B$30<>""),$B$29-$B$3*$B$30,"")
A33: Copy the New Value and paste into the Weight Cell
A36: TRAINING LOG
A38: Epoch | B38: Example | C38: Loss | D38: Notes

Sheet Generate
A1: TEXT GENERATION
A3: Enter your prompt below (up to 8 characters):
A5: Prompt: | B5: the cat
A7: Tokenized Prompt:
A8: Pos 0 | B8: Pos 1 | C8: Pos 2 | D8: Pos 3 | E8: Pos 4 | F8: Pos 5 | G8: Pos 6 | H8: Pos 7
A9: =MID($B$5,1,1) -> t | B9: =MID($B$5,2,1) -> h | C9: =MID($B$5,3,1) -> e | D9: =MID($B$5,4,1) | E9: =MID($B$5,5,1) -> c | F9: =MID($B$5,6,1) -> a | G9: =MID($B$5,7,1) -> t | H9: =MID($B$5,8,1)
A10: =IFERROR(MATCH(A9,Vocab!$B$3:$B$32,0)-1,26) -> 19 | B10: =IFERROR(MATCH(B9,Vocab!$B$3:$B$32,0)-1,26) -> 7 | C10: =IFERROR(MATCH(C9,Vocab!$B$3:$B$32,0)-1,26) -> 4 | D10: =IFERROR(MATCH(D9,Vocab!$B$3:$B$32,0)-1,26) -> 26 | E10: =IFERROR(MATCH(E9,Vocab!$B$3:$B$32,0)-1,26) -> 2 | F10: =IFERROR(MATCH(F9,Vocab!$B$3:$B$32,0)-1,26) -> 0 | G10: =IFERROR(MATCH(G9,Vocab!$B$3:$B$32,0)-1,26) -> 19 | H10: =IFERROR(MATCH(H9,Vocab!$B$3:$B$32,0)-1,26) -> 26
A12: To generate text:
A13: 1. Enter a prompt in B5 (exactly 8 characters, use spaces to pad)
A14: 2. Copy the token IDs above to Corpus row 6 (columns D-K)
A15: 3. Check Output sheet for the predicted next character
A16: 4. Add the predicted character to your prompt
A17: 5. Repeat to generate more text
A19: Note: The model uses the Corpus!D6:K6 cells for input.
A20: You can also directly edit those cells with token IDs.
A24: CURRENT PREDICTION
A26: Predicted Character: | B26: =Output!$B$43
A27: Confidence: | B27: =Output!$B$44 -> 0.063617601
A30: TOP 5 PREDICTIONS
A31: Rank | B31: Character | C31: Probability
A32: 1 | B32: =INDEX(Vocab!$B$3:$B$32,MATCH(LARGE(Output!$B$37:$AE$37,1),Output!$B$37:$AE$37,0)) | C32: =LARGE(Output!$B$37:$AE$37,1) -> 0.063617601
A33: 2 | B33: =INDEX(Vocab!$B$3:$B$32,MATCH(LARGE(Output!$B$37:$AE$37,2),Output!$B$37:$AE$37,0)) -> o | C33: =LARGE(Output!$B$37:$AE$37,2) -> 0.053101136
A34: 3 | B34: =INDEX(Vocab!$B$3:$B$32,MATCH(LARGE(Output!$B$37:$AE$37,3),Output!$B$37:$AE$37,0)) -> w | C34: =LARGE(Output!$B$37:$AE$37,3) -> 0.050508619
A35: 4 | B35: =INDEX(Vocab!$B$3:$B$32,MATCH(LARGE(Output!$B$37:$AE$37,4),Output!$B$37:$AE$37,0)) -> b | C35: =LARGE(Output!$B$37:$AE$37,4) -> 0.04407518
A36: 5 | B36: =INDEX(Vocab!$B$3:$B$32,MATCH(LARGE(Output!$B$37:$AE$37,5),Output!$B$37:$AE$37,0)) -> j | C36: =LARGE(Output!$B$37:$AE$37,5) -> 0.0440329
